Workbook

Sheet Summary
A1: Tuition Ledger — work estimate
A2: Source of truth: 'Work Breakdown'. Edit Base (hd), Risk, Owner, Status there and capacity/contingency in 'Assumptions'.
A4: Headline
A5: Scope | B5: Base (hd) | C5: Estimate (hd) | D5: Estimate (hours) | E5: Person-days | F5: Done (hd) | G5: % done
A6: MVP | B6: =SUMIFS('Work Breakdown'!$L$2:$L$122,'Work Breakdown'!$B$2:$B$122,A6) -> 159 | C6: =SUMIFS('Work Breakdown'!$O$2:$O$122,'Work Breakdown'!$B$2:$B$122,A6) -> 193.5 | D6: =SUMIFS('Work Breakdown'!$P$2:$P$122,'Work Breakdown'!$B$2:$B$122,A6) -> 774 | E6: =C6/2 -> 96.75 | F6: =SUMIFS('Work Breakdown'!$O$2:$O$122,'Work Breakdown'!$B$2:$B$122,A6,'Work Breakdown'!$R$2:$R$122,"Done") -> 2.2 | G6: =IF(C6=0,0,F6/C6) -> 0.011369509
A7: Backlog | B7: =SUMIFS('Work Breakdown'!$L$2:$L$122,'Work Breakdown'!$B$2:$B$122,A7) -> 96 | C7: =SUMIFS('Work Breakdown'!$O$2:$O$122,'Work Breakdown'!$B$2:$B$122,A7) -> 115.2 | D7: =SUMIFS('Work Breakdown'!$P$2:$P$122,'Work Breakdown'!$B$2:$B$122,A7) -> 460.8 | E7: =C7/2 -> 57.6 | F7: =SUMIFS('Work Breakdown'!$O$2:$O$122,'Work Breakdown'!$B$2:$B$122,A7,'Work Breakdown'!$R$2:$R$122,"Done") -> 0 | G7: =IF(C7=0,0,F7/C7) -> 0
A9: MVP by role
A10: Role | B10: Base (hd) | C10: Estimate (hd) | D10: Estimate (hours) | E10: Capacity / sprint (hd) | F10: Sprints needed | G10: Weeks needed
A11: BE | B11: =SUMIFS('Work Breakdown'!$L$2:$L$122,'Work Breakdown'!$B$2:$B$122,"MVP",'Work Breakdown'!$G$2:$G$122,A11) -> 108 | C11: =SUMIFS('Work Breakdown'!$O$2:$O$122,'Work Breakdown'!$B$2:$B$122,"MVP",'Work Breakdown'!$G$2:$G$122,A11) -> 133.025 | D11: =SUMIFS('Work Breakdown'!$P$2:$P$122,'Work Breakdown'!$B$2:$B$122,"MVP",'Work Breakdown'!$G$2:$G$122,A11) -> 532.1 | E11: =INDEX(Assumptions!$B$19:$B$22,MATCH(A11,Assumptions!$A$19:$A$22,0)) -> 20 | F11: =IF(E11=0,0,C11/E11) -> 6.65125 | G11: =F11*Assumptions!$B$4/5 -> 13.3025
A12: FE | B12: =SUMIFS('Work Breakdown'!$L$2:$L$122,'Work Breakdown'!$B$2:$B$122,"MVP",'Work Breakdown'!$G$2:$G$122,A12) -> 36.5 | C12: =SUMIFS('Work Breakdown'!$O$2:$O$122,'Work Breakdown'!$B$2:$B$122,"MVP",'Work Breakdown'!$G$2:$G$122,A12) -> 42.5 | D12: =SUMIFS('Work Breakdown'!$P$2:$P$122,'Work Breakdown'!$B$2:$B$122,"MVP",'Work Breakdown'!$G$2:$G$122,A12) -> 170 | E12: =INDEX(Assumptions!$B$19:$B$22,MATCH(A12,Assumptions!$A$19:$A$22,0)) -> 8 | F12: =IF(E12=0,0,C12/E12) -> 5.3125 | G12: =F12*Assumptions!$B$4/5 -> 10.625
A13: QA | B13: =SUMIFS('Work Breakdown'!$L$2:$L$122,'Work Breakdown'!$B$2:$B$122,"MVP",'Work Breakdown'!$G$2:$G$122,A13) -> 7.5 | C13: =SUMIFS('Work Breakdown'!$O$2:$O$122,'Work Breakdown'!$B$2:$B$122,"MVP",'Work Breakdown'!$G$2:$G$122,A13) -> 8.9 | D13: =SUMIFS('Work Breakdown'!$P$2:$P$122,'Work Breakdown'!$B$2:$B$122,"MVP",'Work Breakdown'!$G$2:$G$122,A13) -> 35.6 | E13: =INDEX(Assumptions!$B$19:$B$22,MATCH(A13,Assumptions!$A$19:$A$22,0)) -> 2 | F13: =IF(E13=0,0,C13/E13) -> 4.45 | G13: =F13*Assumptions!$B$4/5 -> 8.9
A14: PM | B14: =SUMIFS('Work Breakdown'!$L$2:$L$122,'Work Breakdown'!$B$2:$B$122,"MVP",'Work Breakdown'!$G$2:$G$122,A14) -> 7 | C14: =SUMIFS('Work Breakdown'!$O$2:$O$122,'Work Breakdown'!$B$2:$B$122,"MVP",'Work Breakdown'!$G$2:$G$122,A14) -> 9.075 | D14: =SUMIFS('Work Breakdown'!$P$2:$P$122,'Work Breakdown'!$B$2:$B$122,"MVP",'Work Breakdown'!$G$2:$G$122,A14) -> 36.3 | E14: =INDEX(Assumptions!$B$19:$B$22,MATCH(A14,Assumptions!$A$19:$A$22,0)) -> 4 | F14: =IF(E14=0,0,C14/E14) -> 2.26875 | G14: =F14*Assumptions!$B$4/5 -> 4.5375
A15: Critical path (longest role) | F15: =MAX(F11:F14) -> 6.65125 | G15: =MAX(G11:G14) -> 13.3025
A17: MVP load per sprint vs capacity (estimate hd incl. contingency)
A18: Sprint | B18: BE | C18: BE capacity | D18: BE load % | E18: FE | F18: FE capacity | G18: FE load % | H18: QA | I18: PM
A19: S1 | B19: =SUMIFS('Work Breakdown'!$O$2:$O$122,'Work Breakdown'!$I$2:$I$122,A19,'Work Breakdown'!$G$2:$G$122,"BE") -> 31.85 | C19: =Assumptions!$B$19 -> 20 | D19: =IF(C19=0,0,B19/C19) -> 1.5925 | E19: =SUMIFS('Work Breakdown'!$O$2:$O$122,'Work Breakdown'!$I$2:$I$122,A19,'Work Breakdown'!$G$2:$G$122,"FE") -> 10.2 | F19: =Assumptions!$B$20 -> 8 | G19: =IF(F19=0,0,E19/F19) -> 1.275 | H19: =SUMIFS('Work Breakdown'!$O$2:$O$122,'Work Breakdown'!$I$2:$I$122,A19,'Work Breakdown'!$G$2:$G$122,"QA") -> 1.1 | I19: =SUMIFS('Work Breakdown'!$O$2:$O$122,'Work Breakdown'!$I$2:$I$122,A19,'Work Breakdown'!$G$2:$G$122,"PM") -> 0
A20: S2 | B20: =SUMIFS('Work Breakdown'!$O$2:$O$122,'Work Breakdown'!$I$2:$I$122,A20,'Work Breakdown'!$G$2:$G$122,"BE") -> 29.825 | C20: =Assumptions!$B$19 -> 20 | D20: =IF(C20=0,0,B20/C20) -> 1.49125 | E20: =SUMIFS('Work Breakdown'!$O$2:$O$122,'Work Breakdown'!$I$2:$I$122,A20,'Work Breakdown'!$G$2:$G$122,"FE") -> 12.85 | F20: =Assumptions!$B$20 -> 8 | G20: =IF(F20=0,0,E20/F20) -> 1.60625 | H20: =SUMIFS('Work Breakdown'!$O$2:$O$122,'Work Breakdown'!$I$2:$I$122,A20,'Work Breakdown'!$G$2:$G$122,"QA") -> 1.2 | I20: =SUMIFS('Work Breakdown'!$O$2:$O$122,'Work Breakdown'!$I$2:$I$122,A20,'Work Breakdown'!$G$2:$G$122,"PM") -> 0
A21: S3 | B21: =SUMIFS('Work Breakdown'!$O$2:$O$122,'Work Breakdown'!$I$2:$I$122,A21,'Work Breakdown'!$G$2:$G$122,"BE") -> 24.9 | C21: =Assumptions!$B$19 -> 20 | D21: =IF(C21=0,0,B21/C21) -> 1.245 | E21: =SUMIFS('Work Breakdown'!$O$2:$O$122,'Work Breakdown'!$I$2:$I$122,A21,'Work Breakdown'!$G$2:$G$122,"FE") -> 4.6 | F21: =Assumptions!$B$20 -> 8 | G21: =IF(F21=0,0,E21/F21) -> 0.575 | H21: =SUMIFS('Work Breakdown'!$O$2:$O$122,'Work Breakdown'!$I$2:$I$122,A21,'Work Breakdown'!$G$2:$G$122,"QA") -> 1.8 | I21: =SUMIFS('Work Breakdown'!$O$2:$O$122,'Work Breakdown'!$I$2:$I$122,A21,'Work Breakdown'!$G$2:$G$122,"PM") -> 1.35
A22: S4 | B22: =SUMIFS('Work Breakdown'!$O$2:$O$122,'Work Breakdown'!$I$2:$I$122,A22,'Work Breakdown'!$G$2:$G$122,"BE") -> 22.3 | C22: =Assumptions!$B$19 -> 20 | D22: =IF(C22=0,0,B22/C22) -> 1.115 | E22: =SUMIFS('Work Breakdown'!$O$2:$O$122,'Work Breakdown'!$I$2:$I$122,A22,'Work Breakdown'!$G$2:$G$122,"FE") -> 7.7 | F22: =Assumptions!$B$20 -> 8 | G22: =IF(F22=0,0,E22/F22) -> 0.9625 | H22: =SUMIFS('Work Breakdown'!$O$2:$O$122,'Work Breakdown'!$I$2:$I$122,A22,'Work Breakdown'!$G$2:$G$122,"QA") -> 2.4 | I22: =SUMIFS('Work Breakdown'!$O$2:$O$122,'Work Breakdown'!$I$2:$I$122,A22,'Work Breakdown'!$G$2:$G$122,"PM") -> 3.3
A23: S5 | B23: =SUMIFS('Work Breakdown'!$O$2:$O$122,'Work Breakdown'!$I$2:$I$122,A23,'Work Breakdown'!$G$2:$G$122,"BE") -> 24.15 | C23: =Assumptions!$B$19 -> 20 | D23: =IF(C23=0,0,B23/C23) -> 1.2075 | E23: =SUMIFS('Work Breakdown'!$O$2:$O$122,'Work Breakdown'!$I$2:$I$122,A23,'Work Breakdown'!$G$2:$G$122,"FE") -> 7.15 | F23: =Assumptions!$B$20 -> 8 | G23: =IF(F23=0,0,E23/F23) -> 0.89375 | H23: =SUMIFS('Work Breakdown'!$O$2:$O$122,'Work Breakdown'!$I$2:$I$122,A23,'Work Breakdown'!$G$2:$G$122,"QA") -> 2.4 | I23: =SUMIFS('Work Breakdown'!$O$2:$O$122,'Work Breakdown'!$I$2:$I$122,A23,'Work Breakdown'!$G$2:$G$122,"PM") -> 4.425
A24: Over 100% = that sprint is overloaded; move FE rows to the next sprint or add capacity in Assumptions.
A26: MVP by phase (build order)
A27: Phase | B27: BE (hd) | C27: FE (hd) | D27: QA + PM (hd) | E27: Total estimate (hd) | F27: Hours | G27: Done (hd) | H27: % done
A28: P0 Project setup | B28: =SUMIFS('Work Breakdown'!$O$2:$O$122,'Work Breakdown'!$C$2:$C$122,A28,'Work Breakdown'!$G$2:$G$122,"BE") -> 8.2 | C28: =SUMIFS('Work Breakdown'!$O$2:$O$122,'Work Breakdown'!$C$2:$C$122,A28,'Work Breakdown'!$G$2:$G$122,"FE") -> 2.75 | D28: =SUMIFS('Work Breakdown'!$O$2:$O$122,'Work Breakdown'!$C$2:$C$122,A28,'Work Breakdown'!$G$2:$G$122,"QA")+SUMIFS('Work Breakdown'!$O$2:$O$122,'Work Breakdown'!$C$2:$C$122,A28,'Work Breakdown'!$G$2:$G$122,"PM") -> 0 | E28: =SUM(B28:D28) -> 10.95 | F28: =E28*Assumptions!$B$3 -> 43.8 | G28: =SUMIFS('Work Breakdown'!$O$2:$O$122,'Work Breakdown'!$C$2:$C$122,A28,'Work Breakdown'!$R$2:$R$122,"Done") -> 2.2 | H28: =IF(E28=0,0,G28/E28) -> 0.20091324
A29: P1 Tenant provisioning | B29: =SUMIFS('Work Breakdown'!$O$2:$O$122,'Work Breakdown'!$C$2:$C$122,A29,'Work Breakdown'!$G$2:$G$122,"BE") -> 6.6 | C29: =SUMIFS('Work Breakdown'!$O$2:$O$122,'Work Breakdown'!$C$2:$C$122,A29,'Work Breakdown'!$G$2:$G$122,"FE") -> 0 | D29: =SUMIFS('Work Breakdown'!$O$2:$O$122,'Work Breakdown'!$C$2:$C$122,A29,'Work Breakdown'!$G$2:$G$122,"QA")+SUMIFS('Work Breakdown'!$O$2:$O$122,'Work Breakdown'!$C$2:$C$122,A29,'Work Breakdown'!$G$2:$G$122,"PM") -> 0 | E29: =SUM(B29:D29) -> 6.6 | F29: =E29*Assumptions!$B$3 -> 26.4 | G29: =SUMIFS('Work Breakdown'!$O$2:$O$122,'Work Breakdown'!$C$2:$C$122,A29,'Work Breakdown'!$R$2:$R$122,"Done") -> 0 | H29: =IF(E29=0,0,G29/E29) -> 0
A30: P2 Authentication & roles | B30: =SUMIFS('Work Breakdown'!$O$2:$O$122,'Work Breakdown'!$C$2:$C$122,A30,'Work Breakdown'!$G$2:$G$122,"BE") -> 12.275 | C30: =SUMIFS('Work Breakdown'!$O$2:$O$122,'Work Breakdown'!$C$2:$C$122,A30,'Work Breakdown'!$G$2:$G$122,"FE") -> 5.8 | D30: =SUMIFS('Work Breakdown'!$O$2:$O$122,'Work Breakdown'!$C$2:$C$122,A30,'Work Breakdown'!$G$2:$G$122,"QA")+SUMIFS('Work Breakdown'!$O$2:$O$122,'Work Breakdown'!$C$2:$C$122,A30,'Work Breakdown'!$G$2:$G$122,"PM") -> 0 | E30: =SUM(B30:D30) -> 18.075 | F30: =E30*Assumptions!$B$3 -> 72.3 | G30: =SUMIFS('Work Breakdown'!$O$2:$O$122,'Work Breakdown'!$C$2:$C$122,A30,'Work Breakdown'!$R$2:$R$122,"Done") -> 0 | H30: =IF(E30=0,0,G30/E30) -> 0
A31: P3 Batches & sessions | B31: =SUMIFS('Work Breakdown'!$O$2:$O$122,'Work Breakdown'!$C$2:$C$122,A31,'Work Breakdown'!$G$2:$G$122,"BE") -> 3.6 | C31: =SUMIFS('Work Breakdown'!$O$2:$O$122,'Work Breakdown'!$C$2:$C$122,A31,'Work Breakdown'!$G$2:$G$122,"FE") -> 3.3 | D31: =SUMIFS('Work Breakdown'!$O$2:$O$122,'Work Breakdown'!$C$2:$C$122,A31,'Work Breakdown'!$G$2:$G$122,"QA")+SUMIFS('Work Breakdown'!$O$2:$O$122,'Work Breakdown'!$C$2:$C$122,A31,'Work Breakdown'!$G$2:$G$122,"PM") -> 0 | E31: =SUM(B31:D31) -> 6.9 | F31: =E31*Assumptions!$B$3 -> 27.6 | G31: =SUMIFS('Work Breakdown'!$O$2:$O$122,'Work Breakdown'!$C$2:$C$122,A31,'Work Breakdown'!$R$2:$R$122,"Done") -> 0 | H31: =IF(E31=0,0,G31/E31) -> 0
A32: P4 Students & enrolments | B32: =SUMIFS('Work Breakdown'!$O$2:$O$122,'Work Breakdown'!$C$2:$C$122,A32,'Work Breakdown'!$G$2:$G$122,"BE") -> 2.4 | C32: =SUMIFS('Work Breakdown'!$O$2:$O$122,'Work Breakdown'!$C$2:$C$122,A32,'Work Breakdown'!$G$2:$G$122,"FE") -> 2.2 | D32: =SUMIFS('Work Breakdown'!$O$2:$O$122,'Work Breakdown'!$C$2:$C$122,A32,'Work Breakdown'!$G$2:$G$122,"QA")+SUMIFS('Work Breakdown'!$O$2:$O$122,'Work Breakdown'!$C$2:$C$122,A32,'Work Breakdown'!$G$2:$G$122,"PM") -> 0 | E32: =SUM(B32:D32) -> 4.6 | F32: =E32*Assumptions!$B$3 -> 18.4 | G32: =SUMIFS('Work Breakdown'!$O$2:$O$122,'Work Breakdown'!$C$2:$C$122,A32,'Work Breakdown'!$R$2:$R$122,"Done") -> 0 | H32: =IF(E32=0,0,G32/E32) -> 0
A33: P5 Attendance | B33: =SUMIFS('Work Breakdown'!$O$2:$O$122,'Work Breakdown'!$C$2:$C$122,A33,'Work Breakdown'!$G$2:$G$122,"BE") -> 3.5 | C33: =SUMIFS('Work Breakdown'!$O$2:$O$122,'Work Breakdown'!$C$2:$C$122,A33,'Work Breakdown'!$G$2:$G$122,"FE") -> 2.4 | D33: =SUMIFS('Work Breakdown'!$O$2:$O$122,'Work Breakdown'!$C$2:$C$122,A33,'Work Breakdown'!$G$2:$G$122,"QA")+SUMIFS('Work Breakdown'!$O$2:$O$122,'Work Breakdown'!$C$2:$C$122,A33,'Work Breakdown'!$G$2:$G$122,"PM") -> 1.1 | E33: =SUM(B33:D33) -> 7 | F33: =E33*Assumptions!$B$3 -> 28 | G33: =SUMIFS('Work Breakdown'!$O$2:$O$122,'Work Breakdown'!$C$2:$C$122,A33,'Work Breakdown'!$R$2:$R$122,"Done") -> 0 | H33: =IF(E33=0,0,G33/E33) -> 0
A34: P6 Fee engine | B34: =SUMIFS('Work Breakdown'!$O$2:$O$122,'Work Breakdown'!$C$2:$C$122,A34,'Work Breakdown'!$G$2:$G$122,"BE") -> 11.8 | C34: =SUMIFS('Work Breakdown'!$O$2:$O$122,'Work Breakdown'!$C$2:$C$122,A34,'Work Breakdown'!$G$2:$G$122,"FE") -> 1.8 | D34: =SUMIFS('Work Breakdown'!$O$2:$O$122,'Work Breakdown'!$C$2:$C$122,A34,'Work Breakdown'!$G$2:$G$122,"QA")+SUMIFS('Work Breakdown'!$O$2:$O$122,'Work Breakdown'!$C$2:$C$122,A34,'Work Breakdown'!$G$2:$G$122,"PM") -> 0 | E34: =SUM(B34:D34) -> 13.6 | F34: =E34*Assumptions!$B$3 -> 54.4 | G34: =SUMIFS('Work Breakdown'!$O$2:$O$122,'Work Breakdown'!$C$2:$C$122,A34,'Work Breakdown'!$R$2:$R$122,"Done") -> 0 | H34: =IF(E34=0,0,G34/E34) -> 0
A35: P7 Ledger & payments | B35: =SUMIFS('Work Breakdown'!$O$2:$O$122,'Work Breakdown'!$C$2:$C$122,A35,'Work Breakdown'!$G$2:$G$122,"BE") -> 13.3 | C35: =SUMIFS('Work Breakdown'!$O$2:$O$122,'Work Breakdown'!$C$2:$C$122,A35,'Work Breakdown'!$G$2:$G$122,"FE") -> 4.8 | D35: =SUMIFS('Work Breakdown'!$O$2:$O$122,'Work Breakdown'!$C$2:$C$122,A35,'Work Breakdown'!$G$2:$G$122,"QA")+SUMIFS('Work Breakdown'!$O$2:$O$122,'Work Breakdown'!$C$2:$C$122,A35,'Work Breakdown'!$G$2:$G$122,"PM") -> 1.2 | E35: =SUM(B35:D35) -> 19.3 | F35: =E35*Assumptions!$B$3 -> 77.2 | G35: =SUMIFS('Work Breakdown'!$O$2:$O$122,'Work Breakdown'!$C$2:$C$122,A35,'Work Breakdown'!$R$2:$R$122,"Done") -> 0 | H35: =IF(E35=0,0,G35/E35) -> 0
A36: P8 WhatsApp messaging | B36: =SUMIFS('Work Breakdown'!$O$2:$O$122,'Work Breakdown'!$C$2:$C$122,A36,'Work Breakdown'!$G$2:$G$122,"BE") -> 18.65 | C36: =SUMIFS('Work Breakdown'!$O$2:$O$122,'Work Breakdown'!$C$2:$C$122,A36,'Work Breakdown'!$G$2:$G$122,"FE") -> 1.65 | D36: =SUMIFS('Work Breakdown'!$O$2:$O$122,'Work Breakdown'!$C$2:$C$122,A36,'Work Breakdown'!$G$2:$G$122,"QA")+SUMIFS('Work Breakdown'!$O$2:$O$122,'Work Breakdown'!$C$2:$C$122,A36,'Work Breakdown'!$G$2:$G$122,"PM") -> 0.675 | E36: =SUM(B36:D36) -> 20.975 | F36: =E36*Assumptions!$B$3 -> 83.9 | G36: =SUMIFS('Work Breakdown'!$O$2:$O$122,'Work Breakdown'!$C$2:$C$122,A36,'Work Breakdown'!$R$2:$R$122,"Done") -> 0 | H36: =IF(E36=0,0,G36/E36) -> 0
A37: P9 Online payments | B37: =SUMIFS('Work Breakdown'!$O$2:$O$122,'Work Breakdown'!$C$2:$C$122,A37,'Work Breakdown'!$G$2:$G$122,"BE") -> 6.25 | C37: =SUMIFS('Work Breakdown'!$O$2:$O$122,'Work Breakdown'!$C$2:$C$122,A37,'Work Breakdown'!$G$2:$G$122,"FE") -> 2.95 | D37: =SUMIFS('Work Breakdown'!$O$2:$O$122,'Work Breakdown'!$C$2:$C$122,A37,'Work Breakdown'!$G$2:$G$122,"QA")+SUMIFS('Work Breakdown'!$O$2:$O$122,'Work Breakdown'!$C$2:$C$122,A37,'Work Breakdown'!$G$2:$G$122,"PM") -> 2.475 | E37: =SUM(B37:D37) -> 11.675 | F37: =E37*Assumptions!$B$3 -> 46.7 | G37: =SUMIFS('Work Breakdown'!$O$2:$O$122,'Work Breakdown'!$C$2:$C$122,A37,'Work Breakdown'!$R$2:$R$122,"Done") -> 0 | H37: =IF(E37=0,0,G37/E37) -> 0
A38: P10 Reminders & digests | B38: =SUMIFS('Work Breakdown'!$O$2:$O$122,'Work Breakdown'!$C$2:$C$122,A38,'Work Breakdown'!$G$2:$G$122,"BE") -> 6.4 | C38: =SUMIFS('Work Breakdown'!$O$2:$O$122,'Work Breakdown'!$C$2:$C$122,A38,'Work Breakdown'!$G$2:$G$122,"FE") -> 0 | D38: =SUMIFS('Work Breakdown'!$O$2:$O$122,'Work Breakdown'!$C$2:$C$122,A38,'Work Breakdown'!$G$2:$G$122,"QA")+SUMIFS('Work Breakdown'!$O$2:$O$122,'Work Breakdown'!$C$2:$C$122,A38,'Work Breakdown'!$G$2:$G$122,"PM") -> 0 | E38: =SUM(B38:D38) -> 6.4 | F38: =E38*Assumptions!$B$3 -> 25.6 | G38: =SUMIFS('Work Breakdown'!$O$2:$O$122,'Work Breakdown'!$C$2:$C$122,A38,'Work Breakdown'!$R$2:$R$122,"Done") -> 0 | H38: =IF(E38=0,0,G38/E38) -> 0
A39: P11 Dashboard, reports & settings | B39: =SUMIFS('Work Breakdown'!$O$2:$O$122,'Work Breakdown'!$C$2:$C$122,A39,'Work Breakdown'!$G$2:$G$122,"BE") -> 8.7 | C39: =SUMIFS('Work Breakdown'!$O$2:$O$122,'Work Breakdown'!$C$2:$C$122,A39,'Work Breakdown'!$G$2:$G$122,"FE") -> 6.6 | D39: =SUMIFS('Work Breakdown'!$O$2:$O$122,'Work Breakdown'!$C$2:$C$122,A39,'Work Breakdown'!$G$2:$G$122,"QA")+SUMIFS('Work Breakdown'!$O$2:$O$122,'Work Breakdown'!$C$2:$C$122,A39,'Work Breakdown'!$G$2:$G$122,"PM") -> 0 | E39: =SUM(B39:D39) -> 15.3 | F39: =E39*Assumptions!$B$3 -> 61.2 | G39: =SUMIFS('Work Breakdown'!$O$2:$O$122,'Work Breakdown'!$C$2:$C$122,A39,'Work Breakdown'!$R$2:$R$122,"Done") -> 0 | H39: =IF(E39=0,0,G39/E39) -> 0
... A44: P16 Hardening & Gate 3 | B44: =SUMIFS('Work Breakdown'!$O$2:$O$122,'Work Breakdown'!$C$2:$C$122,A44,'Work Breakdown'!$G$2:$G$122,"BE") -> 10.8 | C44: =SUMIFS('Work Breakdown'!$O$2:$O$122,'Work Breakdown'!$C$2:$C$122,A44,'Work Breakdown'!$G$2:$G$122,"FE") -> 0.55 | D44: =SUMIFS('Work Breakdown'!$O$2:$O$122,'Work Breakdown'!$C$2:$C$122,A44,'Work Breakdown'!$G$2:$G$122,"QA")+SUMIFS('Work Breakdown'!$O$2:$O$122,'Work Breakdown'!$C$2:$C$122,A44,'Work Breakdown'!$G$2:$G$122,"PM") -> 6.15 | E44: =SUM(B44:D44) -> 17.5 | F44: =E44*Assumptions!$B$3 -> 70 | G44: =SUMIFS('Work Breakdown'!$O$2:$O$122,'Work Breakdown'!$C$2:$C$122,A44,'Work Breakdown'!$R$2:$R$122,"Done") -> 0 | H44: =IF(E44=0,0,G44/E44) -> 0
A45: Total MVP | B45: =SUM(B28:B44) -> 133.025 | C45: =SUM(C28:C44) -> 42.5 | D45: =SUM(D28:D44) -> 17.975 | E45: =SUM(E28:E44) -> 193.5 | F45: =SUM(F28:F44) -> 774 | G45: =SUM(G28:G44) -> 2.2 | H45: =IF(E45=0,0,G45/E45) -> 0.011369509
A47: Gates
A48: G1 (end S2): September re-entered and the statement balances
A49: G2 (end S4): one live fee cycle, zero duplicate payments
...

Sheet Assumptions
A1: Estimation assumptions (edit blue cells; everything else recalculates)
A3: Hours per half-day (hd) | B3: 4 | C3: 1 hd = half a working day, as used in docs/09-sprint-plan.md
A4: Working days per sprint | B4: 10 | C4: Two-week sprints (docs/09)
A5: Backend devs | B5: 1 | C5: docs/09 capacity assumption: one backend developer
A6: Frontend devs | B6: 1 | C6: docs/09: one part-time frontend developer
A7: Frontend allocation (fraction of full time) | B7: 0.4 | C7: Part-time ≈ 8 hd per sprint, matching docs/09 FE totals
A8: QA hd per sprint | B8: 2 | C8: Shared QA (docs/09)
A9: PM hd per sprint | B9: 4 | C9: Shared PM (docs/09)
A11: Contingency by risk
A12: Risk | B12: Contingency % | C12: Meaning
A13: N | B13: 0 | C13: None — reserved capacity or fixed admin task
A14: L | B14: 0.1 | C14: Low — CRUD / screens with a clear pattern
A15: M | B15: 0.2 | C15: Medium — some unknowns, moderate integration
A16: H | B16: 0.35 | C16: High — money correctness, concurrency, external providers, approvals
A18: Capacity per sprint (hd)
A19: BE | B19: =B4*B5*2 -> 20
A20: FE | B20: =B4*B6*B7*2 -> 8
A21: QA | B21: =B8 -> 2
A22: PM | B22: =B9 -> 4

Sheet Work Breakdown
A1: Seq | B1: Scope | C1: Phase | D1: Feature | E1: Task ID | F1: Task | G1: Role | H1: Depends on | I1: Sprint | J1: SRS | K1: Design ref | L1: Base (hd) | M1: Risk | N1: Contingency % | O1: Estimate (hd) | P1: Estimate (hours) | Q1: Owner | R1: Status | S1: Done when
A2: 1 | B2: MVP | C2: P0 Project setup | D2: Monorepo | E2: NEW-01 | F2: Monorepo layout in this repo: /backend, /frontend, /infra; JDK 21 required; root Makefile (up, down, seed, test); .editorconfig; dev-setup section in README | G2: BE | H2: — | I2: S1 | J2: — | K2: 03 §2 | L2: 0.5 | M2: L | N2: =INDEX(Assumptions!$B$13:$B$16,MATCH(M2,Assumptions!$A$13:$A$16,0)) -> 0.1 | O2: =L2*(1+N2) -> 0.55 | P2: =O2*Assumptions!$B$3 -> 2.2 | R2: Not started | S2: Fresh clone + `make up` works from README steps
A3: 2 | B3: MVP | C3: P0 Project setup | D3: Backend skeleton | E3: S1-01 | F3: Backend: Maven (wrapper), Java 21, Spring Boot 4.1, Spring Modulith with 9 modules + shared kernel and ModularityTests | G3: BE | H3: NEW-01 | I3: S1 | J3: — | K3: 04 §0 | L3: 1 | M3: L | N3: =INDEX(Assumptions!$B$13:$B$16,MATCH(M3,Assumptions!$A$13:$A$16,0)) -> 0.1 | O3: =L3*(1+N3) -> 1.1 | P3: =O3*Assumptions!$B$3 -> 4.4 | R3: Done | S3: `./mvnw test` passes ModularityTests
A4: 3 | B4: MVP | C4: P0 Project setup | D4: Frontend skeleton | E4: S1-13a | F4: Frontend: Vite + React 18 + TypeScript strict, ESLint/Prettier, Vitest + Testing Library, React Router, TanStack Query, folder-per-feature (split from S1-13) | G4: FE | H4: NEW-01 | I4: S1 | J4: — | K4: 04 §12, ADR-0014 | L4: 1 | M4: L | N4: =INDEX(Assumptions!$B$13:$B$16,MATCH(M4,Assumptions!$A$13:$A$16,0)) -> 0.1 | O4: =L4*(1+N4) -> 1.1 | P4: =O4*Assumptions!$B$3 -> 4.4 | R4: Done | S4: `npm run lint`, `test`, `build` all green
A5: 4 | B5: MVP | C5: P0 Project setup | D5: Config | E5: NEW-02 | F5: Environment config: Spring profiles dev/test/prod, .env.example, Vite env vars, no secrets in git | G5: BE | H5: S1-01 | I5: S1 | J5: — | K5: 11 | L5: 0.5 | M5: L | N5: =INDEX(Assumptions!$B$13:$B$16,MATCH(M5,Assumptions!$A$13:$A$16,0)) -> 0.1 | O5: =L5*(1+N5) -> 0.55 | P5: =O5*Assumptions!$B$3 -> 2.2 | R5: In progress | S5: App boots from .env.example values
A6: 5 | B6: MVP | C6: P0 Project setup | D6: Local stack | E6: S1-02 | F6: Docker Compose: app, Postgres 16, Redis, Prometheus, Grafana, WhatsApp fake UI; Vite dev proxy to API | G6: BE | H6: S1-01 | I6: S1 | J6: — | K6: 03 §2 | L6: 1 | M6: M | N6: =INDEX(Assumptions!$B$13:$B$16,MATCH(M6,Assumptions!$A$13:$A$16,0)) -> 0.2 | O6: =L6*(1+N6) -> 1.2 | P6: =O6*Assumptions!$B$3 -> 4.8 | R6: Not started | S6: `make up` brings the stack; /actuator/health green
A7: 6 | B7: MVP | C7: P0 Project setup | D7: CI | E7: NEW-03 | F7: GitHub Actions: backend `./mvnw verify` (Testcontainers), frontend lint + test + build, path filters; set both as required checks on protect-main | G7: BE | H7: S1-01, S1-13a | I7: S1 | J7: — | K7: 13 | L7: 1 | M7: M | N7: =INDEX(Assumptions!$B$13:$B$16,MATCH(M7,Assumptions!$A$13:$A$16,0)) -> 0.2 | O7: =L7*(1+N7) -> 1.2 | P7: =O7*Assumptions!$B$3 -> 4.8 | R7: Not started | S7: PR shows both checks; merge blocked when red
A8: 7 | B8: MVP | C8: P0 Project setup | D8: Shared kernel | E8: S1-04 | F8: Shared kernel: Money, ULID Ids, Clock, TenantContext, CentreTime, problem-details handler, ArchUnit no-float rule | G8: BE | H8: S1-01 | I8: S1 | J8: NFR-7 | K8: 04 §1, §11 | L8: 2 | M8: M | N8: =INDEX(Assumptions!$B$13:$B$16,MATCH(M8,Assumptions!$A$13:$A$16,0)) -> 0.2 | O8: =L8*(1+N8) -> 2.4 | P8: =O8*Assumptions!$B$3 -> 9.6 | R8: Not started | S8: Unit tests; ArchUnit rule green
A9: 8 | B9: MVP | C9: P0 Project setup | D9: API client | E9: S1-13b | F9: OpenAPI → TypeScript client generation script; CI fails if openapi.yaml changed without regenerating (split from S1-13) | G9: FE | H9: S1-13a, NEW-03 | I9: S1 | J9: — | K9: 06, ADR-0014 | L9: 0.5 | M9: L | N9: =INDEX(Assumptions!$B$13:$B$16,MATCH(M9,Assumptions!$A$13:$A$16,0)) -> 0.1 | O9: =L9*(1+N9) -> 0.55 | P9: =O9*Assumptions!$B$3 -> 2.2 | R9: Not started | S9: Drift check fails CI on purpose-made mismatch
A10: 9 | B10: MVP | C10: P0 Project setup | D10: Design system | E10: S1-13c | F10: Design tokens + base components: button, input, form field with server errors, list/table, money formatter with tabular numerals (split from S1-13) | G10: FE | H10: S1-13a | I10: S1 | J10: NFR-6 | K10: 04 §12 | L10: 1 | M10: L | N10: =INDEX(Assumptions!$B$13:$B$16,MATCH(M10,Assumptions!$A$13:$A$16,0)) -> 0.1 | O10: =L10*(1+N10) -> 1.1 | P10: =O10*Assumptions!$B$3 -> 4.4 | R10: Not started | S10: Components render at 360 px
A11: 10 | B11: MVP | C11: P0 Project setup | D11: Ops baseline | E11: S1-16 | F11: Nightly pg_dump to object storage, restore script, Uptime Kuma, Grafana v0, alert to phone on health down | G11: BE | H11: S1-02 | I11: S1 | J11: NFR-4 | K11: 12 | L11: 1 | M11: M | N11: =INDEX(Assumptions!$B$13:$B$16,MATCH(M11,Assumptions!$A$13:$A$16,0)) -> 0.2 | O11: =L11*(1+N11) -> 1.2 | P11: =O11*Assumptions!$B$3 -> 4.8 | R11: Not started | S11: Restore into a fresh container demonstrated and logged
A12: 11 | B12: MVP | C12: P1 Tenant provisioning | D12: Schema | E12: S1-03 | F12: Flyway baseline tenant tables (centres, users, settings, audit_log, batches, sessions, students, enrolments, attendance, holidays) with RLS policies and tl_app grants | G12: BE | H12: S1-01 | I12: S1 | J12: — | K12: 05 | L12: 2 | M12: H | N12: =INDEX(Assumptions!$B$13:$B$16,MATCH(M12,Assumptions!$A$13:$A$16,0)) -> 0.35 | O12: =L12*(1+N12) -> 2.7 | P12: =O12*Assumptions!$B$3 -> 10.8 | R12: Not started | S12: Migrations idempotent; UPDATE on audit_log fails in a test
A13: 12 | B13: MVP | C13: P1 Tenant provisioning | D13: Centre creation | E13: NEW-04 | F13: Centre provisioning: platform-admin endpoint + CLI command creating centre, owner user and default settings; validates CEN-1 fields (timezone, due day, quiet hours, receipt prefix) | G13: BE | H13: S1-03, S1-04 | I13: S1 | J13: CEN-1, PLT-1 | K13: 04 §2, 07 | L13: 1 | M13: M | N13: =INDEX(Assumptions!$B$13:$B$16,MATCH(M13,Assumptions!$A$13:$A$16,0)) -> 0.2 | O13: =L13*(1+N13) -> 1.2 | P13: =O13*Assumptions!$B$3 -> 4.8 | R13: Not started | S13: New centre + owner created in one call; invalid prefix rejected
... A122: 121 | B122: Backlog | C122: Phase 4 · add-ons | D122: Roadmap item | E122: BL-17 | F122: Multilingual everything | G122: BE/FE | H122: MVP | I122: Phase 4 | J122: I18N-2..3 | K122: 15-roadmap | L122: 8 | M122: M | N122: =INDEX(Assumptions!$B$13:$B$16,MATCH(M122,Assumptions!$A$13:$A$16,0)) -> 0.2 | O122: =L122*(1+N122) -> 9.6 | P122: =O122*Assumptions!$B$3 -> 38.4 | R122: Not started | S122: Not committed — size from 15-roadmap.md

Sheet How to use
A1: How to use this workbook
A3: 1. 'Work Breakdown' lists every task in build order (Seq). Tenant provisioning comes before auth; each backend API comes before the screen that uses it.
A4: 2. Yellow cells are yours to edit: Base (hd), Risk (N/L/M/H), Owner, Status. Blue text = input values.
A5: 3. Estimate (hd) = Base × (1 + contingency for the risk level). Hours = Estimate × hours per hd (Assumptions).
A6: 4. 'Summary' recalculates totals, sprints needed per role, per-sprint load vs capacity, and % done from Status.
A7: 5. Task IDs: S#-## = ticket from docs/09-sprint-plan.md; S1-13a..e / S1-14a,b / S5-11a = tickets split for clarity; NEW-## = work missing from the sprint plan; BL-## = roadmap backlog (not committed).
A8: 6. Example row: Seq 14 · S1-05 · BE · Base 3 hd · Risk H → 3 × 1.35 = 4.05 hd ≈ 16 h.
A10: Repo layout assumed (monorepo, this repo): /backend (Spring Boot, Gradle), /frontend (React + Vite), /infra (Docker Compose, deploy), /docs.
A11: Branching: every task = one branch + one PR into main (main is protected).
